<?xml version="1.0"?>
<sdf version="1.10">
    <model name="skid-loader-635">
        <link name="arm_link">
            <pose>-0.83545 7e-05 1.23389 1.5708 0 0</pose>
            <inertial>
                <mass>200.0</mass>
                <inertia>
                    <ixx>2e-05</ixx>
                    <ixy>0</ixy>
                    <ixz>0</ixz>
                    <iyy>3e-05</iyy>
                    <iyz>0</iyz>
                    <izz>2e-05</izz>
                </inertia>
                <pose>0 0 0 0 0 0</pose>
            </inertial>
            <collision name="Boom">
                <pose>0 0 0 -1.5708 -1.5708 0</pose>
                <geometry>
                    <mesh>
                        <uri>model://skid-loader-635/meshes/Mesh.092.stl</uri>
                        <scale>1.0 1.0 1.0</scale>
                    </mesh>
                </geometry>
            </collision>
            <visual name="Boom">
                <pose>-5.960464477539063e-08 -1.1470236219168761e-11 0.0 -1.5707964897155762 -1.5707961320877075
                    0.0
                </pose>
                <material>
                    <ambient>0.81569 0.70196 0.70196 1.0</ambient>
                    <diffuse>0.81569 0.70196 0.17647 1.0</diffuse>
                    <specular>1.0 1.0 1.0 1.0</specular>
                </material>
                <geometry>
                    <mesh>
                        <uri>model://skid-loader-635/meshes/Mesh.003.stl</uri>
                        <scale>0.02261 0.02261 0.02261</scale>
                    </mesh>
                </geometry>
            </visual>
        </link>
        <link name="base_link">
            <pose>0 0 0 0 0 0</pose>
        </link>
        <link name="body_link">
            <pose>0 0 0.3 0 0 0</pose>
            <inertial>
                <mass>200.0</mass>
                <inertia>
                    <ixx>2e-05</ixx>
                    <ixy>0</ixy>
                    <ixz>0</ixz>
                    <iyy>2e-05</iyy>
                    <iyz>0</iyz>
                    <izz>3e-05</izz>
                </inertia>
                <pose>0 0 0 0 0 0</pose>
            </inertial>
            <collision name="body_frame">
                <pose>-0.17428 3e-05 0.43976 0 0 -1.5708</pose>
                <geometry>
                    <box>
                        <size>1.02686 1.68031 1.18317</size>
                    </box>
                </geometry>
            </collision>
            <visual name="body_frame">
                <pose>-3.552906802312475e-15 1.6200374375330284e-12 0.0 -1.1920928955078125e-07
                    1.1920928244535389e-07 -1.5707963705062866
                </pose>
                <material>
                    <ambient>0.81569 0.70196 0.70196 1.0</ambient>
                    <diffuse>0.81569 0.70196 0.17647 1.0</diffuse>
                    <specular>1.0 1.0 1.0 1.0</specular>
                </material>
                <geometry>
                    <mesh>
                        <uri>model://skid-loader-635/meshes/Mesh.019.stl</uri>
                        <scale>0.02261 0.02261 0.02261</scale>
                    </mesh>
                </geometry>
            </visual>
            <sensor name="navsat_sensor" type="navsat">
                <pose>0 0 0 0 0 0</pose>
                <topic>gnss_pos</topic>
                <update_rate>20</update_rate>
                <alwaysOn>1</alwaysOn>
                <visualize>1</visualize>
                <navsat>
                    <position_sensing>
                        <vertical>
                            <noise type='gaussian'>
                                <mean>0</mean>
                                <stddev>4.49158e-07</stddev> <!-- 5 cm in spherical coordinates-->
                                <bias_mean>0</bias_mean>
                            </noise>
                        </vertical>
                        <horizontal>
                            <noise type='gaussian'>
                                <mean>0</mean>
                                <stddev>1.8087389541e-07</stddev> <!-- 2 cm in spherical coordinates-->
                                <bias_mean>0</bias_mean>
                            </noise>
                        </horizontal>
                    </position_sensing>
                    <velocity_sensing>
                        <vertical>
                            <noise type='gaussian'>
                                <mean>
                                </mean>
                                <stddev>0</stddev>
                                <bias_mean>0</bias_mean>
                            </noise>
                        </vertical>
                        <horizontal>
                            <noise type='gaussian'>
                                <mean>0</mean>
                                <stddev>0</stddev>
                                <bias_mean>0</bias_mean>
                            </noise>
                        </horizontal>
                    </velocity_sensing>
                </navsat>
            </sensor>
            <sensor name="imu_sensor" type="imu">
                <always_on>1</always_on>
                <update_rate>100</update_rate>
                <visualize>true</visualize>
                <topic>imu</topic>
                <!-- Noise from ADIS16448 IMU -->
                <angular_velocity>
                    <x>
                        <noise type="gaussian">
                            <mean>0.0</mean>
                            <stddev>0.003393695767766752</stddev>
                            <bias_mean>0.0000075</bias_mean>
                            <bias_stddev>0.008726646259971648</bias_stddev>
                            <dynamic_bias_stddev>3.878509448876288e-05</dynamic_bias_stddev>
                            <dynamic_bias_correlation_time>300.0</dynamic_bias_correlation_time>
                            <precision>0</precision>
                        </noise>
                    </x>
                    <y>
                        <noise type="gaussian">
                            <mean>0.0</mean>
                            <stddev>0.003393695767766752</stddev>
                            <bias_mean>0.0000075</bias_mean>
                            <bias_stddev>0.008726646259971648</bias_stddev>
                            <dynamic_bias_stddev>3.878509448876288e-05</dynamic_bias_stddev>
                            <dynamic_bias_correlation_time>300.0</dynamic_bias_correlation_time>
                            <precision>0</precision>
                        </noise>
                    </y>
                    <z>
                        <noise type="gaussian">
                            <mean>0.0</mean>
                            <stddev>0.003393695767766752</stddev>
                            <bias_mean>0.0000075</bias_mean>
                            <bias_stddev>0.008726646259971648</bias_stddev>
                            <dynamic_bias_stddev>3.878509448876288e-05</dynamic_bias_stddev>
                            <dynamic_bias_correlation_time>300.0</dynamic_bias_correlation_time>
                            <precision>0</precision>
                        </noise>
                    </z>
                </angular_velocity>
                <linear_acceleration>
                    <x>
                        <noise type="gaussian">
                            <mean>0.0</mean>
                            <stddev>0.003393695767766752</stddev>
                            <bias_mean>0.0000075</bias_mean>
                            <bias_stddev>0.008726646259971648</bias_stddev>
                            <dynamic_bias_stddev>3.878509448876288e-05</dynamic_bias_stddev>
                            <dynamic_bias_correlation_time>300.0</dynamic_bias_correlation_time>
                            <precision>0</precision>
                        </noise>
                    </x>
                    <y>
                        <noise type="gaussian">
                            <mean>0.0</mean>
                            <stddev>0.003393695767766752</stddev>
                            <bias_mean>0.0000075</bias_mean>
                            <bias_stddev>0.008726646259971648</bias_stddev>
                            <dynamic_bias_stddev>3.878509448876288e-05</dynamic_bias_stddev>
                            <dynamic_bias_correlation_time>300.0</dynamic_bias_correlation_time>
                            <precision>0</precision>
                        </noise>
                    </y>
                    <z>
                        <noise type="gaussian">
                            <mean>0.0</mean>
                            <stddev>0.003393695767766752</stddev>
                            <bias_mean>0.0000075</bias_mean>
                            <bias_stddev>0.008726646259971648</bias_stddev>
                            <dynamic_bias_stddev>3.878509448876288e-05</dynamic_bias_stddev>
                            <dynamic_bias_correlation_time>300.0</dynamic_bias_correlation_time>
                            <precision>0</precision>
                        </noise>
                    </z>
                </linear_acceleration>
            </sensor>
        </link>
        <link name="right_front_wheel_link">
            <pose>0.40254 -0.52145 0.29995 -1.5708 1.5708 0</pose>
            <inertial>
                <mass>50.0</mass>
                <inertia>
                    <ixx>2e-05</ixx>
                    <ixy>0</ixy>
                    <ixz>0</ixz>
                    <iyy>2e-05</iyy>
                    <iyz>0</iyz>
                    <izz>2e-05</izz>
                </inertia>
                <pose>0 0 0 0 0 0</pose>
            </inertial>
            <collision name="Wheel2">
                <pose>-0.00076 0 0.00737 -3.14159 0 -1.5708</pose>
                <geometry>
                    <cylinder>
                        <radius>0.29776</radius>
                        <length>0.23924</length>
                    </cylinder>
                </geometry>
            </collision>
            <visual name="Wheel2">
                <pose>5.886597875814914e-10 0.0 0.0 3.141592502593994 1.570796251296997 0.0</pose>
                <material>
                    <ambient>0.28627 0.30588 0.30588 1.0</ambient>
                    <diffuse>0.28627 0.30588 0.31373 1.0</diffuse>
                    <specular>1.0 1.0 1.0 1.0</specular>
                </material>
                <geometry>
                    <mesh>
                        <uri>model://skid-loader-635/meshes/Mesh.016.stl</uri>
                        <scale>0.02261 0.02261 0.02261</scale>
                    </mesh>
                </geometry>
            </visual>
        </link>
        <link name="right_rear_wheel_link">
            <pose>-0.40253 -0.52145 0.29995 -1.5708 1.5708 0</pose>
            <inertial>
                <mass>50.0</mass>
                <inertia>
                    <ixx>2e-05</ixx>
                    <ixy>0</ixy>
                    <ixz>0</ixz>
                    <iyy>2e-05</iyy>
                    <iyz>0</iyz>
                    <izz>2e-05</izz>
                </inertia>
                <pose>0 0 0 0 0 0</pose>
            </inertial>
            <collision name="Wheel2">
                <pose>0 0 0 -3.14159 0 -1.5708</pose>
                <geometry>
                    <cylinder>
                        <radius>0.29776</radius>
                        <length>0.23924</length>
                    </cylinder>
                </geometry>
            </collision>
            <visual name="Wheel4">
                <pose>-5.879954301235557e-10 0.0 0.0 3.141592502593994 1.570796251296997 0.0</pose>
                <material>
                    <ambient>0.28627 0.30588 0.30588 1.0</ambient>
                    <diffuse>0.28627 0.30588 0.31373 1.0</diffuse>
                    <specular>1.0 1.0 1.0 1.0</specular>
                </material>
                <geometry>
                    <mesh>
                        <uri>model://skid-loader-635/meshes/Mesh.018.stl</uri>
                        <scale>0.02261 0.02261 0.02261</scale>
                    </mesh>
                </geometry>
            </visual>
        </link>
        <link name="left_rear_wheel_link">
            <pose>-0.40253 0.52151 0.29995 -1.5708 -1.5708 0</pose>
            <inertial>
                <mass>50.0</mass>
                <inertia>
                    <ixx>2e-05</ixx>
                    <ixy>0</ixy>
                    <ixz>0</ixz>
                    <iyy>2e-05</iyy>
                    <iyz>0</iyz>
                    <izz>2e-05</izz>
                </inertia>
                <pose>0 0 0 0 0 0</pose>
            </inertial>
            <collision name="Wheel2">
                <pose>0 0 0 -3.14159 0 1.5708</pose>
                <geometry>
                    <cylinder>
                        <radius>0.29776</radius>
                        <length>0.23924</length>
                    </cylinder>
                </geometry>
            </collision>
            <visual name="Wheel3">
                <pose>1.1031119129256695e-08 0.0 0.0 7.549789415861596e-08 1.570796251296997 0.0</pose>
                <material>
                    <ambient>0.28627 0.30588 0.30588 1.0</ambient>
                    <diffuse>0.28627 0.30588 0.31373 1.0</diffuse>
                    <specular>1.0 1.0 1.0 1.0</specular>
                </material>
                <geometry>
                    <mesh>
                        <uri>model://skid-loader-635/meshes/Mesh.017.stl</uri>
                        <scale>0.02261 0.02261 0.02261</scale>
                    </mesh>
                </geometry>
            </visual>
        </link>
        <link name="left_front_wheel_link">
            <pose>0.40254 0.52137 0.30016 -1.5708 -1.5708 0</pose>
            <inertial>
                <mass>50.0</mass>
                <inertia>
                    <ixx>2e-05</ixx>
                    <ixy>0</ixy>
                    <ixz>0</ixz>
                    <iyy>2e-05</iyy>
                    <iyz>0</iyz>
                    <izz>2e-05</izz>
                </inertia>
                <pose>0 0 0 0 0 0</pose>
            </inertial>
            <collision name="Wheel2">
                <pose>0 0 0 -3.14159 0 1.5708</pose>
                <geometry>
                    <cylinder>
                        <radius>0.29776</radius>
                        <length>0.23924</length>
                    </cylinder>
                </geometry>
            </collision>
            <visual name="Wheel1">
                <pose>-1.1029378299554082e-08 0.0 0.0 7.549789415861596e-08 1.570796251296997 0.0</pose>
                <material>
                    <ambient>0.28627 0.30588 0.30588 1.0</ambient>
                    <diffuse>0.28627 0.30588 0.31373 1.0</diffuse>
                    <specular>1.0 1.0 1.0 1.0</specular>
                </material>
                <geometry>
                    <mesh>
                        <uri>model://skid-loader-635/meshes/Mesh.015.stl</uri>
                        <scale>0.02261 0.02261 0.02261</scale>
                    </mesh>
                </geometry>
            </visual>
        </link>
        <link name="bucket_link">
            <pose>0.73721 3e-05 0.17884 1.5708 0 0</pose>
            <inertial>
                <mass>200.0</mass>
                <inertia>
                    <ixx>2e-05</ixx>
                    <ixy>0</ixy>
                    <ixz>0</ixz>
                    <iyy>2e-05</iyy>
                    <iyz>0</iyz>
                    <izz>2e-05</izz>
                </inertia>
                <pose>0 0 0 0 0 0</pose>
            </inertial>
            <collision name="bucket">
                <pose>0 0 0 -1.13351 -1.5708 0</pose>
                <geometry>
                    <mesh>
                        <uri>model://skid-loader-635/meshes/Mesh.100.stl</uri>
                        <scale>1.0 1.0 1.0</scale>
                    </mesh>
                </geometry>
            </collision>
            <visual name="bucket_visual">
                <pose>0.0 2.9796778377999544e-08 3.637978807091713e-12 -1.1335108280181885 -1.5707961320877075 0.0
                </pose>
                <material>
                    <ambient>0.12941 0.12941 0.12941 1.0</ambient>
                    <diffuse>0.12941 0.12941 0.12941 1.0</diffuse>
                    <specular>1.0 1.0 1.0 1.0</specular>
                </material>
                <geometry>
                    <mesh>
                        <uri>model://skid-loader-635/meshes/Mesh.026.stl</uri>
                        <scale>0.02261 0.02261 0.02261</scale>
                    </mesh>
                </geometry>
            </visual>
        </link>
        <link name="engine_visual_link">
            <pose>-1.18554 0.00366 0.67313 1.5708 0 -1.5708</pose>
            <inertial>
                <mass>200.0</mass>
                <inertia>
                    <ixx>2e-05</ixx>
                    <ixy>0</ixy>
                    <ixz>0</ixz>
                    <iyy>2e-05</iyy>
                    <iyz>0</iyz>
                    <izz>2e-05</izz>
                </inertia>
                <pose>-0.02138 -0.10455 -0.13168 0 0 0</pose>
            </inertial>
            <collision name="EngineCover">
                <pose>0.00287 0.02425 -0.12881 0 0 0</pose>
                <geometry>
                    <box>
                        <size>0.7654 0.73749 0.27329</size>
                    </box>
                </geometry>
            </collision>
            <visual name="EngineCover">
                <pose>0.0 -7.782976041426082e-09 0.0 0.0 -0.0 1.4632987352082918e-22</pose>
                <material>
                    <ambient>0.12941 0.12941 0.12941 1.0</ambient>
                    <diffuse>0.12941 0.12941 0.12941 1.0</diffuse>
                    <specular>1.0 1.0 1.0 1.0</specular>
                </material>
                <geometry>
                    <mesh>
                        <uri>model://skid-loader-635/meshes/Mesh.104.stl</uri>
                        <scale>0.02261 0.02261 0.02261</scale>
                    </mesh>
                </geometry>
            </visual>
        </link>
        <link name="cage_link">
            <pose>0.01387 2e-05 1.05024 0 0 0</pose>
            <inertial>
                <mass>200.0</mass>
                <inertia>
                    <ixx>2e-05</ixx>
                    <ixy>0</ixy>
                    <ixz>0</ixz>
                    <iyy>3e-05</iyy>
                    <iyz>0</iyz>
                    <izz>2e-05</izz>
                </inertia>
                <pose>-0.27759 3e-05 0.00728 0 0 0</pose>
            </inertial>
            <collision name="Cabine Out">
                <pose>-0.1388 1e-05 0.00364 0 0 -1.5708</pose>
                <geometry>
                    <box>
                        <size>0.73701 1.2443 1.07031</size>
                    </box>
                </geometry>
            </collision>
            <visual name="cabin_cage">
                <pose>-0.01386982947587967 -2.0612314983736724e-05 -0.7502354979515076 -1.1920928244535389e-07 -0.0
                    -1.5707964897155762
                </pose>
                <material>
                    <ambient>0.12941 0.12941 0.12941 1.0</ambient>
                    <diffuse>0.12941 0.12941 0.12941 1.0</diffuse>
                    <specular>1.0 1.0 1.0 1.0</specular>
                </material>
                <geometry>
                    <mesh>
                        <uri>model://skid-loader-635/meshes/Mesh.090.stl</uri>
                        <scale>0.02261 0.02261 0.02261</scale>
                    </mesh>
                </geometry>
            </visual>
        </link>
        <link name="link_body_imu_sensor">
            <pose>-0.91418 2e-05 1.01588 0 0 0</pose>
        </link>
        <link name="link_GNSS1_sensor">
            <pose>0 0 0 0 0 0</pose>
        </link>
        <joint name="arm_joint" type="fixed">
            <parent>body_link</parent>
            <child>arm_link</child>
            <pose>0.0 0.0 0.0 0.0 0.0 0.0</pose>
        </joint>
        <joint name="body_joint" type="fixed">
            <parent>base_link</parent>
            <child>body_link</child>
            <pose>0.0 0.0 0.0 0.0 0.0 0.0</pose>
        </joint>
        <joint name="right_front_wheel_joint" type="revolute">
            <parent>body_link</parent>
            <child>right_front_wheel_link</child>
            <pose>0.0 0.0 0.0 0.0 0.0 0.0</pose>
            <axis>
                <xyz>0 0 1.0</xyz>
            </axis>
        </joint>
        <joint name="right_rear_wheel_joint" type="revolute">
            <parent>body_link</parent>
            <child>right_rear_wheel_link</child>
            <pose>0.0 0.0 0.0 0.0 0.0 0.0</pose>
            <axis>
                <xyz>0 0 1.0</xyz>
            </axis>
        </joint>
        <joint name="left_rear_wheel_joint" type="revolute">
            <parent>body_link</parent>
            <child>left_rear_wheel_link</child>
            <pose>0.0 0.0 0.0 0.0 0.0 0.0</pose>
            <axis>
                <xyz>0 0 1.0</xyz>
            </axis>
        </joint>
        <joint name="left_front_wheel_joint" type="revolute">
            <parent>body_link</parent>
            <child>left_front_wheel_link</child>
            <pose>0.0 0.0 0.0 0.0 0.0 0.0</pose>
            <axis>
                <xyz>0 0 1.0</xyz>
            </axis>
        </joint>
        <joint name="bucket_joint" type="fixed">
            <parent>arm_link</parent>
            <child>bucket_link</child>
            <pose>0.0 0.0 0.0 0.0 0.0 0.0</pose>
        </joint>
        <joint name="engine_visual_joint" type="fixed">
            <parent>body_link</parent>
            <child>engine_visual_link</child>
            <pose>0.0 0.0 0.0 0.0 0.0 0.0</pose>
        </joint>
        <joint name="cage_visual_joint" type="fixed">
            <parent>body_link</parent>
            <child>cage_link</child>
            <pose>0.0 0.0 0.0 0.0 0.0 0.0</pose>
        </joint>
        <joint name="body_imu_joint" type="fixed">
            <parent>base_link</parent>
            <child>link_body_imu_sensor</child>
            <pose>0.0 0.0 0.0 0.0 0.0 0.0</pose>
        </joint>
        <joint name="gnss_sensor_joint" type="fixed">
            <parent>body_link</parent>
            <child>link_GNSS1_sensor</child>
            <pose>0.0 0.0 0.0 0.0 0.0 0.0</pose>
        </joint>
        <!--diff drive plugin-->
        <plugin
                filename="gz-sim-diff-drive-system"
                name="gz::sim::systems::DiffDrive">
            <num_wheel_pairs>2</num_wheel_pairs>
            <left_joint>left_front_wheel_joint</left_joint>
            <right_joint>right_front_wheel_joint</right_joint>
            <left_joint>left_rear_wheel_joint</left_joint>
            <right_joint>right_rear_wheel_joint</right_joint>
            <wheel_separation>1.03</wheel_separation>
            <wheel_radius>0.3</wheel_radius>
            <odom_publish_frequency>0</odom_publish_frequency>
            <odom_topic>drive/odom</odom_topic>>
            <topic>cmd_vel</topic>
            <max_linear_acceleration>3</max_linear_acceleration>
            <min_linear_acceleration>-3</min_linear_acceleration>
            <max_angular_acceleration>5</max_angular_acceleration>
            <min_angular_acceleration>-5</min_angular_acceleration>
            <max_linear_velocity>10.5</max_linear_velocity>
            <min_linear_velocity>-10.5</min_linear_velocity>
            <max_angular_velocity>5</max_angular_velocity>
            <min_angular_velocity>-5</min_angular_velocity>
            <child_frame_id>skid-loader-635/base_link</child_frame_id>
        </plugin>
        <plugin
                filename="gz-sim-odometry-publisher-system"
                name="gz::sim::systems::OdometryPublisher">
            <publish_link_pose>true</publish_link_pose>
            <publish_collision_pose>false</publish_collision_pose>
            <publish_visual_pose>false</publish_visual_pose>
            <publish_nested_model_pose>false</publish_nested_model_pose>
            <robot_base_frame>base_link</robot_base_frame>
            <gaussian_noise>0.0</gaussian_noise>
            <dimensions>3</dimensions>
            <odom_topic>base_link_true_pose/odom</odom_topic>
            <odom_publish_frequency>100</odom_publish_frequency> <!-- Matches fastest sensor input -->
        </plugin>
        <!-- Logging -->
        <plugin
                filename="gz-sim-pose-publisher-system"
                name="gz::sim::systems::PosePublisher">
            <publish_link_pose>true</publish_link_pose>
            <publish_sensor_pose>true</publish_sensor_pose>
            <publish_collision_pose>false</publish_collision_pose>
            <publish_visual_pose>false</publish_visual_pose>
            <publish_nested_model_pose>false</publish_nested_model_pose>
        </plugin>
        <plugin
                filename="InsCsvLogger"
                name="csv_logger::csv_logger">
        </plugin>
    </model>
</sdf>
